{
  "schema_version": "1.4.0",
  "id": "GHSA-66h8-g4c7-pp34",
  "modified": "2025-04-20T03:45:24Z",
  "published": "2022-05-14T01:44:58Z",
  "aliases": [
    "CVE-2017-14503"
  ],
  "details": "libarchive 3.3.2 suffers from an out-of-bounds read within lha_read_data_none() in archive_read_support_format_lha.c when extracting a specially crafted lha archive, related to lha_crc16.",
  "severity": [
    {
      "type": "CVSS_V3",
      "score": "CVSS:3.0/AV:N/AC:L/PR:N/UI:R/S:U/C:N/I:N/A:H"
    }
  ],
  "affected": [],
  "references": [
    {
      "type": "ADVISORY",
      "url": "https://nvd.nist.gov/vuln/detail/CVE-2017-14503"
    },
    {
      "type": "WEB",
      "url": "https://github.com/libarchive/libarchive/issues/948"
    },
    {
      "type": "WEB",
      "url": "https://access.redhat.com/errata/RHSA-2019:2298"
    },
    {
      "type": "WEB",
      "url": "https://access.redhat.com/errata/RHSA-2019:3698"
    },
    {
      "type": "WEB",
      "url": "https://bugs.debian.org/875960"
    },
    {
      "type": "WEB",
      "url": "https://lists.debian.org/debian-lts-announce/2018/11/msg00037.html"
    },
    {
      "type": "WEB",
      "url": "https://security.gentoo.org/glsa/201908-11"
    },
    {
      "type": "WEB",
      "url": "https://usn.ubuntu.com/3736-1"
    },
    {
      "type": "WEB",
      "url": "https://www.debian.org/security/2018/dsa-4360"
    }
  ],
  "database_specific": {
    "cwe_ids": [
      "CWE-125"
    ],
    "severity": "MODERATE",
    "github_reviewed": false,
    "github_reviewed_at": null,
    "nvd_published_at": "2017-09-17T18:29:00Z"
  }
}