{
  "schema_version": "1.4.0",
  "id": "GHSA-3749-ghw9-m3mg",
  "modified": "2025-03-30T18:30:24Z",
  "published": "2025-03-30T18:30:24Z",
  "aliases": [
    "CVE-2025-2953"
  ],
  "details": "A vulnerability, which was classified as problematic, has been found in PyTorch 2.6.0+cu124. Affected by this issue is the function torch.mkldnn_max_pool2d. The manipulation leads to denial of service. An attack has to be approached locally. The exploit has been disclosed to the public and may be used.",
  "severity": [
    {
      "type": "CVSS_V3",
      "score": "CVSS:3.1/AV:L/AC:L/PR:L/UI:N/S:U/C:N/I:N/A:L"
    },
    {
      "type": "CVSS_V4",
      "score": "CVSS:4.0/AV:L/AC:L/AT:N/PR:L/UI:N/VC:N/VI:N/VA:L/SC:N/SI:N/SA:N/E:X/CR:X/IR:X/AR:X/MAV:X/MAC:X/MAT:X/MPR:X/MUI:X/MVC:X/MVI:X/MVA:X/MSC:X/MSI:X/MSA:X/S:X/AU:X/R:X/V:X/RE:X/U:X"
    }
  ],
  "affected": [],
  "references": [
    {
      "type": "ADVISORY",
      "url": "https://nvd.nist.gov/vuln/detail/CVE-2025-2953"
    },
    {
      "type": "WEB",
      "url": "https://github.com/pytorch/pytorch/issues/149274"
    },
    {
      "type": "WEB",
      "url": "https://github.com/pytorch/pytorch/issues/149274#issue-2923122269"
    },
    {
      "type": "WEB",
      "url": "https://vuldb.com/?ctiid.302006"
    },
    {
      "type": "WEB",
      "url": "https://vuldb.com/?id.302006"
    },
    {
      "type": "WEB",
      "url": "https://vuldb.com/?submit.521279"
    }
  ],
  "database_specific": {
    "cwe_ids": [
      "CWE-404"
    ],
    "severity": "MODERATE",
    "github_reviewed": false,
    "github_reviewed_at": null,
    "nvd_published_at": "2025-03-30T16:15:14Z"
  }
}